
time="2025-08-18T22:40:18Z" level=warning msg="/home/ubuntu/rinha-de-backend-2025/participantes/joney-sousa-pereira/docker-compose.yml: the attribute `version` is obsolete, it will be ignored, please remove it to avoid potential confusion"
 Network joney-sousa-pereira_rinha-network  Creating
 Network joney-sousa-pereira_rinha-network  Created
 Volume "joney-sousa-pereira_redis_data"  Creating
 Volume "joney-sousa-pereira_redis_data"  Created
 Volume "joney-sousa-pereira_postgres_data"  Creating
 Volume "joney-sousa-pereira_postgres_data"  Created
 Container python-rinha-postgres  Creating
 Container python-rinha-redis  Creating
 Container python-rinha-postgres  Created
 Container python-rinha-redis  Created
 Container python-rinha-app1  Creating
 Container python-rinha-app2  Creating
 Container python-rinha-app2  Created
 Container python-rinha-app1  Created
 Container python-rinha-nginx  Creating
 Container python-rinha-nginx  Created
Attaching to python-rinha-app1, python-rinha-app2, python-rinha-nginx, python-rinha-postgres, python-rinha-redis
python-rinha-postgres  | The files belonging to this database system will be owned by user "postgres".
python-rinha-postgres  | This user must also own the server process.
python-rinha-postgres  | 
python-rinha-postgres  | The database cluster will be initialized with locale "en_US.utf8".
python-rinha-postgres  | The default database encoding has accordingly been set to "UTF8".
python-rinha-postgres  | The default text search configuration will be set to "english".
python-rinha-postgres  | 
python-rinha-postgres  | Data page checksums are disabled.
python-rinha-postgres  | 
python-rinha-postgres  | fixing permissions on existing directory /var/lib/postgresql/data ... ok
python-rinha-postgres  | creating subdirectories ... ok
python-rinha-postgres  | selecting dynamic shared memory implementation ... posix
python-rinha-redis     | 1:C 18 Aug 2025 22:40:19.286 # WARNING Memory overcommit must be enabled! Without it, a background save or replication may fail under low memory condition. Being disabled, it can also cause failures without low memory condition, see https://github.com/jemalloc/jemalloc/issues/1328. To fix this issue add 'vm.overcommit_memory = 1' to /etc/sysctl.conf and then reboot or run the command 'sysctl vm.overcommit_memory=1' for this to take effect.
python-rinha-redis     | 1:C 18 Aug 2025 22:40:19.286 * oO0OoO0OoO0Oo Redis is starting oO0OoO0OoO0Oo
python-rinha-redis     | 1:C 18 Aug 2025 22:40:19.286 * Redis version=7.4.5, bits=64, commit=00000000, modified=0, pid=1, just started
python-rinha-redis     | 1:C 18 Aug 2025 22:40:19.286 * Configuration loaded
python-rinha-redis     | 1:M 18 Aug 2025 22:40:19.286 * monotonic clock: POSIX clock_gettime
python-rinha-redis     | 1:M 18 Aug 2025 22:40:19.287 * Running mode=standalone, port=6379.
python-rinha-redis     | 1:M 18 Aug 2025 22:40:19.287 * Server initialized
python-rinha-redis     | 1:M 18 Aug 2025 22:40:19.294 * Creating AOF base file appendonly.aof.1.base.rdb on server start
python-rinha-redis     | 1:M 18 Aug 2025 22:40:19.301 * Creating AOF incr file appendonly.aof.1.incr.aof on server start
python-rinha-redis     | 1:M 18 Aug 2025 22:40:19.301 * Ready to accept connections tcp
python-rinha-postgres  | selecting default max_connections ... 100
python-rinha-postgres  | selecting default shared_buffers ... 128MB
python-rinha-postgres  | selecting default time zone ... UTC
python-rinha-postgres  | creating configuration files ... ok
python-rinha-nginx     | /docker-entrypoint.sh: /docker-entrypoint.d/ is not empty, will attempt to perform configuration
python-rinha-nginx     | /docker-entrypoint.sh: Looking for shell scripts in /docker-entrypoint.d/
python-rinha-nginx     | /docker-entrypoint.sh: Launching /docker-entrypoint.d/10-listen-on-ipv6-by-default.sh
python-rinha-nginx     | 10-listen-on-ipv6-by-default.sh: info: Getting the checksum of /etc/nginx/conf.d/default.conf
python-rinha-nginx     | 10-listen-on-ipv6-by-default.sh: info: Enabled listen on IPv6 in /etc/nginx/conf.d/default.conf
python-rinha-nginx     | /docker-entrypoint.sh: Sourcing /docker-entrypoint.d/15-local-resolvers.envsh
python-rinha-nginx     | /docker-entrypoint.sh: Launching /docker-entrypoint.d/20-envsubst-on-templates.sh
python-rinha-nginx     | /docker-entrypoint.sh: Launching /docker-entrypoint.d/30-tune-worker-processes.sh
python-rinha-nginx     | /docker-entrypoint.sh: Configuration complete; ready for start up
python-rinha-postgres  | running bootstrap script ... ok
python-rinha-postgres  | sh: locale: not found
python-rinha-postgres  | 2025-08-18 22:40:21.096 UTC [35] WARNING:  no usable system locales were found
python-rinha-app2      | Traceback (most recent call last):
python-rinha-app2      |   File "/usr/local/lib/python3.11/site-packages/sqlalchemy/engine/base.py", line 145, in __init__
python-rinha-app1      | Traceback (most recent call last):
python-rinha-app1      |   File "/usr/local/lib/python3.11/site-packages/sqlalchemy/engine/base.py", line 145, in __init__
python-rinha-app2      |     self._dbapi_connection = engine.raw_connection()
python-rinha-app2      |                              ^^^^^^^^^^^^^^^^^^^^^^^
python-rinha-app2      |   File "/usr/local/lib/python3.11/site-packages/sqlalchemy/engine/base.py", line 3292, in raw_connection
python-rinha-app1      |     self._dbapi_connection = engine.raw_connection()
python-rinha-app1      |                              ^^^^^^^^^^^^^^^^^^^^^^^
python-rinha-app1      |   File "/usr/local/lib/python3.11/site-packages/sqlalchemy/engine/base.py", line 3292, in raw_connection
python-rinha-app2      |     return self.pool.connect()
python-rinha-app1      |     return self.pool.connect()
python-rinha-app1      |            ^^^^^^^^^^^^^^^^^^^
python-rinha-app1      |   File "/usr/local/lib/python3.11/site-packages/sqlalchemy/pool/base.py", line 452, in connect
python-rinha-app2      |            ^^^^^^^^^^^^^^^^^^^
python-rinha-app2      |   File "/usr/local/lib/python3.11/site-packages/sqlalchemy/pool/base.py", line 452, in connect
python-rinha-app1      |     return _ConnectionFairy._checkout(self)
python-rinha-app2      |     return _ConnectionFairy._checkout(self)
python-rinha-app2      |            ^^^^^^^^^^^^^^^^^^^^^^^^^^^^^^^^
python-rinha-app2      |   File "/usr/local/lib/python3.11/site-packages/sqlalchemy/pool/base.py", line 1269, in _checkout
python-rinha-app1      |            ^^^^^^^^^^^^^^^^^^^^^^^^^^^^^^^^
python-rinha-app1      |   File "/usr/local/lib/python3.11/site-packages/sqlalchemy/pool/base.py", line 1269, in _checkout
python-rinha-app2      |     fairy = _ConnectionRecord.checkout(pool)
python-rinha-app2      |             ^^^^^^^^^^^^^^^^^^^^^^^^^^^^^^^^
python-rinha-app2      |   File "/usr/local/lib/python3.11/site-packages/sqlalchemy/pool/base.py", line 716, in checkout
python-rinha-app1      |     fairy = _ConnectionRecord.checkout(pool)
python-rinha-app1      |             ^^^^^^^^^^^^^^^^^^^^^^^^^^^^^^^^
python-rinha-app1      |   File "/usr/local/lib/python3.11/site-packages/sqlalchemy/pool/base.py", line 716, in checkout
python-rinha-app2      |     rec = pool._do_get()
python-rinha-app2      |           ^^^^^^^^^^^^^^
python-rinha-app2      |   File "/usr/local/lib/python3.11/site-packages/sqlalchemy/pool/impl.py", line 169, in _do_get
python-rinha-app1      |     rec = pool._do_get()
python-rinha-app1      |           ^^^^^^^^^^^^^^
python-rinha-app1      |   File "/usr/local/lib/python3.11/site-packages/sqlalchemy/pool/impl.py", line 169, in _do_get
python-rinha-app1      |     with util.safe_reraise():
python-rinha-app1      |   File "/usr/local/lib/python3.11/site-packages/sqlalchemy/util/langhelpers.py", line 146, in __exit__
python-rinha-app2      |     with util.safe_reraise():
python-rinha-app2      |   File "/usr/local/lib/python3.11/site-packages/sqlalchemy/util/langhelpers.py", line 146, in __exit__
python-rinha-app2      |     raise exc_value.with_traceback(exc_tb)
python-rinha-app2      |   File "/usr/local/lib/python3.11/site-packages/sqlalchemy/pool/impl.py", line 167, in _do_get
python-rinha-app1      |     raise exc_value.with_traceback(exc_tb)
python-rinha-app1      |   File "/usr/local/lib/python3.11/site-packages/sqlalchemy/pool/impl.py", line 167, in _do_get
python-rinha-app1      |     return self._create_connection()
python-rinha-app1      |            ^^^^^^^^^^^^^^^^^^^^^^^^^
python-rinha-app1      |   File "/usr/local/lib/python3.11/site-packages/sqlalchemy/pool/base.py", line 393, in _create_connection
python-rinha-app1      |     return _ConnectionRecord(self)
python-rinha-app2      |     return self._create_connection()
python-rinha-app2      |            ^^^^^^^^^^^^^^^^^^^^^^^^^
python-rinha-app2      |   File "/usr/local/lib/python3.11/site-packages/sqlalchemy/pool/base.py", line 393, in _create_connection
python-rinha-app2      |     return _ConnectionRecord(self)
python-rinha-app2      |            ^^^^^^^^^^^^^^^^^^^^^^^
python-rinha-app2      |   File "/usr/local/lib/python3.11/site-packages/sqlalchemy/pool/base.py", line 678, in __init__
python-rinha-app2      |     self.__connect()
python-rinha-app2      |   File "/usr/local/lib/python3.11/site-packages/sqlalchemy/pool/base.py", line 902, in __connect
python-rinha-app2      |     with util.safe_reraise():
python-rinha-app2      |   File "/usr/local/lib/python3.11/site-packages/sqlalchemy/util/langhelpers.py", line 146, in __exit__
python-rinha-app1      |            ^^^^^^^^^^^^^^^^^^^^^^^
python-rinha-app1      |   File "/usr/local/lib/python3.11/site-packages/sqlalchemy/pool/base.py", line 678, in __init__
python-rinha-app2      |     raise exc_value.with_traceback(exc_tb)
python-rinha-app2      |   File "/usr/local/lib/python3.11/site-packages/sqlalchemy/pool/base.py", line 898, in __connect
python-rinha-app1      |     self.__connect()
python-rinha-app1      |   File "/usr/local/lib/python3.11/site-packages/sqlalchemy/pool/base.py", line 902, in __connect
python-rinha-app1      |     with util.safe_reraise():
python-rinha-app1      |   File "/usr/local/lib/python3.11/site-packages/sqlalchemy/util/langhelpers.py", line 146, in __exit__
python-rinha-app2      |     self.dbapi_connection = connection = pool._invoke_creator(self)
python-rinha-app1      |     raise exc_value.with_traceback(exc_tb)
python-rinha-app1      |   File "/usr/local/lib/python3.11/site-packages/sqlalchemy/pool/base.py", line 898, in __connect
python-rinha-app1      |     self.dbapi_connection = connection = pool._invoke_creator(self)
python-rinha-app2      |                                          ^^^^^^^^^^^^^^^^^^^^^^^^^^
python-rinha-app2      |   File "/usr/local/lib/python3.11/site-packages/sqlalchemy/engine/create.py", line 637, in connect
python-rinha-app1      |                                          ^^^^^^^^^^^^^^^^^^^^^^^^^^
python-rinha-app1      |   File "/usr/local/lib/python3.11/site-packages/sqlalchemy/engine/create.py", line 637, in connect
python-rinha-app1      |     return dialect.connect(*cargs, **cparams)
python-rinha-app1      |            ^^^^^^^^^^^^^^^^^^^^^^^^^^^^^^^^^^
python-rinha-app1      |   File "/usr/local/lib/python3.11/site-packages/sqlalchemy/engine/default.py", line 616, in connect
python-rinha-app2      |     return dialect.connect(*cargs, **cparams)
python-rinha-app2      |            ^^^^^^^^^^^^^^^^^^^^^^^^^^^^^^^^^^
python-rinha-app2      |   File "/usr/local/lib/python3.11/site-packages/sqlalchemy/engine/default.py", line 616, in connect
python-rinha-app2      |     return self.loaded_dbapi.connect(*cargs, **cparams)
python-rinha-app1      |     return self.loaded_dbapi.connect(*cargs, **cparams)
python-rinha-app2      |            ^^^^^^^^^^^^^^^^^^^^^^^^^^^^^^^^^^^^^^^^^^^^
python-rinha-app2      |   File "/usr/local/lib/python3.11/site-packages/psycopg2/__init__.py", line 122, in connect
python-rinha-app1      |            ^^^^^^^^^^^^^^^^^^^^^^^^^^^^^^^^^^^^^^^^^^^^
python-rinha-app1      |   File "/usr/local/lib/python3.11/site-packages/psycopg2/__init__.py", line 122, in connect
python-rinha-app2      |     conn = _connect(dsn, connection_factory=connection_factory, **kwasync)
python-rinha-app1      |     conn = _connect(dsn, connection_factory=connection_factory, **kwasync)
python-rinha-app1      |            ^^^^^^^^^^^^^^^^^^^^^^^^^^^^^^^^^^^^^^^^^^^^^^^^^^^^^^^^^^^^^^^
python-rinha-app1      | psycopg2.OperationalError: connection to server at "postgres" (172.21.0.2), port 5432 failed: Connection refused
python-rinha-app1      | 	Is the server running on that host and accepting TCP/IP connections?
python-rinha-app1      | 
python-rinha-app1      | 
python-rinha-app1      | The above exception was the direct cause of the following exception:
python-rinha-app1      | 
python-rinha-app1      | Traceback (most recent call last):
python-rinha-app1      |   File "/app/uvicorn_config.py", line 6, in <module>
python-rinha-app1      |     from app import app
python-rinha-app1      |   File "/app/app.py", line 66, in <module>
python-rinha-app2      |            ^^^^^^^^^^^^^^^^^^^^^^^^^^^^^^^^^^^^^^^^^^^^^^^^^^^^^^^^^^^^^^^
python-rinha-app2      | psycopg2.OperationalError: connection to server at "postgres" (172.21.0.2), port 5432 failed: Connection refused
python-rinha-app2      | 	Is the server running on that host and accepting TCP/IP connections?
python-rinha-app2      | 
python-rinha-app2      | 
python-rinha-app2      | The above exception was the direct cause of the following exception:
python-rinha-app2      | 
python-rinha-app2      | Traceback (most recent call last):
python-rinha-app2      |   File "/app/uvicorn_config.py", line 6, in <module>
python-rinha-app1      |     Base.metadata.create_all(bind=engine)
python-rinha-app1      |   File "/usr/local/lib/python3.11/site-packages/sqlalchemy/sql/schema.py", line 5828, in create_all
python-rinha-app2      |     from app import app
python-rinha-app2      |   File "/app/app.py", line 66, in <module>
python-rinha-app2      |     Base.metadata.create_all(bind=engine)
python-rinha-app2      |   File "/usr/local/lib/python3.11/site-packages/sqlalchemy/sql/schema.py", line 5828, in create_all
python-rinha-app2      |     bind._run_ddl_visitor(
python-rinha-app2      |   File "/usr/local/lib/python3.11/site-packages/sqlalchemy/engine/base.py", line 3242, in _run_ddl_visitor
python-rinha-app1      |     bind._run_ddl_visitor(
python-rinha-app1      |   File "/usr/local/lib/python3.11/site-packages/sqlalchemy/engine/base.py", line 3242, in _run_ddl_visitor
python-rinha-app2      |     with self.begin() as conn:
python-rinha-app2      |   File "/usr/local/lib/python3.11/contextlib.py", line 137, in __enter__
python-rinha-app1      |     with self.begin() as conn:
python-rinha-app1      |   File "/usr/local/lib/python3.11/contextlib.py", line 137, in __enter__
python-rinha-app1      |     return next(self.gen)
python-rinha-app1      |            ^^^^^^^^^^^^^^
python-rinha-app1      |   File "/usr/local/lib/python3.11/site-packages/sqlalchemy/engine/base.py", line 3232, in begin
python-rinha-app2      |     return next(self.gen)
python-rinha-app2      |            ^^^^^^^^^^^^^^
python-rinha-app2      |   File "/usr/local/lib/python3.11/site-packages/sqlalchemy/engine/base.py", line 3232, in begin
python-rinha-app2      |     with self.connect() as conn:
python-rinha-app2      |          ^^^^^^^^^^^^^^
python-rinha-app2      |   File "/usr/local/lib/python3.11/site-packages/sqlalchemy/engine/base.py", line 3268, in connect
python-rinha-app2      |     return self._connection_cls(self)
python-rinha-app2      |            ^^^^^^^^^^^^^^^^^^^^^^^^^^
python-rinha-app2      |   File "/usr/local/lib/python3.11/site-packages/sqlalchemy/engine/base.py", line 147, in __init__
python-rinha-app2      |     Connection._handle_dbapi_exception_noconnection(
python-rinha-app2      |   File "/usr/local/lib/python3.11/site-packages/sqlalchemy/engine/base.py", line 2430, in _handle_dbapi_exception_noconnection
python-rinha-app2      |     raise sqlalchemy_exception.with_traceback(exc_info[2]) from e
python-rinha-app2      |   File "/usr/local/lib/python3.11/site-packages/sqlalchemy/engine/base.py", line 145, in __init__
python-rinha-app2      |     self._dbapi_connection = engine.raw_connection()
python-rinha-app2      |                              ^^^^^^^^^^^^^^^^^^^^^^^
python-rinha-app2      |   File "/usr/local/lib/python3.11/site-packages/sqlalchemy/engine/base.py", line 3292, in raw_connection
python-rinha-app2      |     return self.pool.connect()
python-rinha-app2      |            ^^^^^^^^^^^^^^^^^^^
python-rinha-app2      |   File "/usr/local/lib/python3.11/site-packages/sqlalchemy/pool/base.py", line 452, in connect
python-rinha-app2      |     return _ConnectionFairy._checkout(self)
python-rinha-app2      |            ^^^^^^^^^^^^^^^^^^^^^^^^^^^^^^^^
python-rinha-app2      |   File "/usr/local/lib/python3.11/site-packages/sqlalchemy/pool/base.py", line 1269, in _checkout
python-rinha-app2      |     fairy = _ConnectionRecord.checkout(pool)
python-rinha-app2      |             ^^^^^^^^^^^^^^^^^^^^^^^^^^^^^^^^
python-rinha-app2      |   File "/usr/local/lib/python3.11/site-packages/sqlalchemy/pool/base.py", line 716, in checkout
python-rinha-app1      |     with self.connect() as conn:
python-rinha-app1      |          ^^^^^^^^^^^^^^
python-rinha-app1      |   File "/usr/local/lib/python3.11/site-packages/sqlalchemy/engine/base.py", line 3268, in connect
python-rinha-app2      |     rec = pool._do_get()
python-rinha-app2      |           ^^^^^^^^^^^^^^
python-rinha-app2      |   File "/usr/local/lib/python3.11/site-packages/sqlalchemy/pool/impl.py", line 169, in _do_get
python-rinha-app2      |     with util.safe_reraise():
python-rinha-app2      |   File "/usr/local/lib/python3.11/site-packages/sqlalchemy/util/langhelpers.py", line 146, in __exit__
python-rinha-app2      |     raise exc_value.with_traceback(exc_tb)
python-rinha-app2      |   File "/usr/local/lib/python3.11/site-packages/sqlalchemy/pool/impl.py", line 167, in _do_get
python-rinha-app2      |     return self._create_connection()
python-rinha-app2      |            ^^^^^^^^^^^^^^^^^^^^^^^^^
python-rinha-app2      |   File "/usr/local/lib/python3.11/site-packages/sqlalchemy/pool/base.py", line 393, in _create_connection
python-rinha-app2      |     return _ConnectionRecord(self)
python-rinha-app2      |            ^^^^^^^^^^^^^^^^^^^^^^^
python-rinha-app2      |   File "/usr/local/lib/python3.11/site-packages/sqlalchemy/pool/base.py", line 678, in __init__
python-rinha-app2      |     self.__connect()
python-rinha-app2      |   File "/usr/local/lib/python3.11/site-packages/sqlalchemy/pool/base.py", line 902, in __connect
python-rinha-app1      |     return self._connection_cls(self)
python-rinha-app1      |            ^^^^^^^^^^^^^^^^^^^^^^^^^^
python-rinha-app1      |   File "/usr/local/lib/python3.11/site-packages/sqlalchemy/engine/base.py", line 147, in __init__
python-rinha-app2      |     with util.safe_reraise():
python-rinha-app2      |   File "/usr/local/lib/python3.11/site-packages/sqlalchemy/util/langhelpers.py", line 146, in __exit__
python-rinha-app1      |     Connection._handle_dbapi_exception_noconnection(
python-rinha-app1      |   File "/usr/local/lib/python3.11/site-packages/sqlalchemy/engine/base.py", line 2430, in _handle_dbapi_exception_noconnection
python-rinha-app2      |     raise exc_value.with_traceback(exc_tb)
python-rinha-app2      |   File "/usr/local/lib/python3.11/site-packages/sqlalchemy/pool/base.py", line 898, in __connect
python-rinha-app1      |     raise sqlalchemy_exception.with_traceback(exc_info[2]) from e
python-rinha-app1      |   File "/usr/local/lib/python3.11/site-packages/sqlalchemy/engine/base.py", line 145, in __init__
python-rinha-app2      |     self.dbapi_connection = connection = pool._invoke_creator(self)
python-rinha-app1      |     self._dbapi_connection = engine.raw_connection()
python-rinha-app1      |                              ^^^^^^^^^^^^^^^^^^^^^^^
python-rinha-app1      |   File "/usr/local/lib/python3.11/site-packages/sqlalchemy/engine/base.py", line 3292, in raw_connection
python-rinha-app2      |                                          ^^^^^^^^^^^^^^^^^^^^^^^^^^
python-rinha-app2      |   File "/usr/local/lib/python3.11/site-packages/sqlalchemy/engine/create.py", line 637, in connect
python-rinha-app2      |     return dialect.connect(*cargs, **cparams)
python-rinha-app2      |            ^^^^^^^^^^^^^^^^^^^^^^^^^^^^^^^^^^
python-rinha-app2      |   File "/usr/local/lib/python3.11/site-packages/sqlalchemy/engine/default.py", line 616, in connect
python-rinha-app2      |     return self.loaded_dbapi.connect(*cargs, **cparams)
python-rinha-app1      |     return self.pool.connect()
python-rinha-app2      |            ^^^^^^^^^^^^^^^^^^^^^^^^^^^^^^^^^^^^^^^^^^^^
python-rinha-app2      |   File "/usr/local/lib/python3.11/site-packages/psycopg2/__init__.py", line 122, in connect
python-rinha-app1      |            ^^^^^^^^^^^^^^^^^^^
python-rinha-app1      |   File "/usr/local/lib/python3.11/site-packages/sqlalchemy/pool/base.py", line 452, in connect
python-rinha-app1      |     return _ConnectionFairy._checkout(self)
python-rinha-app1      |            ^^^^^^^^^^^^^^^^^^^^^^^^^^^^^^^^
python-rinha-app1      |   File "/usr/local/lib/python3.11/site-packages/sqlalchemy/pool/base.py", line 1269, in _checkout
python-rinha-app2      |     conn = _connect(dsn, connection_factory=connection_factory, **kwasync)
python-rinha-app2      |            ^^^^^^^^^^^^^^^^^^^^^^^^^^^^^^^^^^^^^^^^^^^^^^^^^^^^^^^^^^^^^^^
python-rinha-app2      | sqlalchemy.exc.OperationalError: (psycopg2.OperationalError) connection to server at "postgres" (172.21.0.2), port 5432 failed: Connection refused
python-rinha-app2      | 	Is the server running on that host and accepting TCP/IP connections?
python-rinha-app2      | 
python-rinha-app2      | (Background on this error at: https://sqlalche.me/e/20/e3q8)
python-rinha-app1      |     fairy = _ConnectionRecord.checkout(pool)
python-rinha-app1      |             ^^^^^^^^^^^^^^^^^^^^^^^^^^^^^^^^
python-rinha-app1      |   File "/usr/local/lib/python3.11/site-packages/sqlalchemy/pool/base.py", line 716, in checkout
python-rinha-app1      |     rec = pool._do_get()
python-rinha-app1      |           ^^^^^^^^^^^^^^
python-rinha-app1      |   File "/usr/local/lib/python3.11/site-packages/sqlalchemy/pool/impl.py", line 169, in _do_get
python-rinha-app1      |     with util.safe_reraise():
python-rinha-app1      |   File "/usr/local/lib/python3.11/site-packages/sqlalchemy/util/langhelpers.py", line 146, in __exit__
python-rinha-app1      |     raise exc_value.with_traceback(exc_tb)
python-rinha-app1      |   File "/usr/local/lib/python3.11/site-packages/sqlalchemy/pool/impl.py", line 167, in _do_get
python-rinha-app1      |     return self._create_connection()
python-rinha-app1      |            ^^^^^^^^^^^^^^^^^^^^^^^^^
python-rinha-app1      |   File "/usr/local/lib/python3.11/site-packages/sqlalchemy/pool/base.py", line 393, in _create_connection
python-rinha-app1      |     return _ConnectionRecord(self)
python-rinha-app1      |            ^^^^^^^^^^^^^^^^^^^^^^^
python-rinha-app1      |   File "/usr/local/lib/python3.11/site-packages/sqlalchemy/pool/base.py", line 678, in __init__
python-rinha-app1      |     self.__connect()
python-rinha-app1      |   File "/usr/local/lib/python3.11/site-packages/sqlalchemy/pool/base.py", line 902, in __connect
python-rinha-app1      |     with util.safe_reraise():
python-rinha-app1      |   File "/usr/local/lib/python3.11/site-packages/sqlalchemy/util/langhelpers.py", line 146, in __exit__
python-rinha-app1      |     raise exc_value.with_traceback(exc_tb)
python-rinha-app1      |   File "/usr/local/lib/python3.11/site-packages/sqlalchemy/pool/base.py", line 898, in __connect
python-rinha-app1      |     self.dbapi_connection = connection = pool._invoke_creator(self)
python-rinha-app1      |                                          ^^^^^^^^^^^^^^^^^^^^^^^^^^
python-rinha-app1      |   File "/usr/local/lib/python3.11/site-packages/sqlalchemy/engine/create.py", line 637, in connect
python-rinha-app1      |     return dialect.connect(*cargs, **cparams)
python-rinha-app1      |            ^^^^^^^^^^^^^^^^^^^^^^^^^^^^^^^^^^
python-rinha-app1      |   File "/usr/local/lib/python3.11/site-packages/sqlalchemy/engine/default.py", line 616, in connect
python-rinha-app1      |     return self.loaded_dbapi.connect(*cargs, **cparams)
python-rinha-app1      |            ^^^^^^^^^^^^^^^^^^^^^^^^^^^^^^^^^^^^^^^^^^^^
python-rinha-app1      |   File "/usr/local/lib/python3.11/site-packages/psycopg2/__init__.py", line 122, in connect
python-rinha-app1      |     conn = _connect(dsn, connection_factory=connection_factory, **kwasync)
python-rinha-app1      |            ^^^^^^^^^^^^^^^^^^^^^^^^^^^^^^^^^^^^^^^^^^^^^^^^^^^^^^^^^^^^^^^
python-rinha-app1      | sqlalchemy.exc.OperationalError: (psycopg2.OperationalError) connection to server at "postgres" (172.21.0.2), port 5432 failed: Connection refused
python-rinha-app1      | 	Is the server running on that host and accepting TCP/IP connections?
python-rinha-app1      | 
python-rinha-app1      | (Background on this error at: https://sqlalche.me/e/20/e3q8)
[Kpython-rinha-app2 exited with code 1
[Kpython-rinha-app1 exited with code 1
python-rinha-postgres  | performing post-bootstrap initialization ... ok
python-rinha-postgres  | syncing data to disk ... ok
python-rinha-postgres  | 
python-rinha-postgres  | 
python-rinha-postgres  | Success. You can now start the database server using:
python-rinha-postgres  | 
python-rinha-postgres  |     pg_ctl -D /var/lib/postgresql/data -l logfile start
python-rinha-postgres  | 
python-rinha-postgres  | initdb: warning: enabling "trust" authentication for local connections
python-rinha-postgres  | initdb: hint: You can change this by editing pg_hba.conf or using the option -A, or --auth-local and --auth-host, the next time you run initdb.
python-rinha-postgres  | waiting for server to start....2025-08-18 22:40:24.223 UTC [41] LOG:  starting PostgreSQL 15.13 on x86_64-pc-linux-musl, compiled by gcc (Alpine 14.2.0) 14.2.0, 64-bit
python-rinha-postgres  | 2025-08-18 22:40:24.226 UTC [41] LOG:  listening on Unix socket "/var/run/postgresql/.s.PGSQL.5432"
python-rinha-postgres  | 2025-08-18 22:40:24.238 UTC [44] LOG:  database system was shut down at 2025-08-18 22:40:23 UTC
python-rinha-postgres  | 2025-08-18 22:40:24.294 UTC [41] LOG:  database system is ready to accept connections
python-rinha-postgres  |  done
python-rinha-postgres  | server started
python-rinha-postgres  | CREATE DATABASE
python-rinha-postgres  | 
python-rinha-postgres  | 
python-rinha-postgres  | /usr/local/bin/docker-entrypoint.sh: running /docker-entrypoint-initdb.d/init.sql
python-rinha-postgres  | CREATE TABLE
python-rinha-postgres  | CREATE INDEX
python-rinha-postgres  | CREATE INDEX
python-rinha-postgres  | CREATE INDEX
python-rinha-postgres  | CREATE TABLE
python-rinha-postgres  | CREATE INDEX
python-rinha-postgres  | CREATE INDEX
python-rinha-postgres  | 
python-rinha-postgres  | 
python-rinha-postgres  | waiting for server to shut down...2025-08-18 22:40:24.693 UTC [41] LOG:  received fast shutdown request
python-rinha-postgres  | .2025-08-18 22:40:24.696 UTC [41] LOG:  aborting any active transactions
python-rinha-postgres  | 2025-08-18 22:40:24.698 UTC [41] LOG:  background worker "logical replication launcher" (PID 47) exited with exit code 1
python-rinha-postgres  | 2025-08-18 22:40:24.700 UTC [42] LOG:  shutting down
python-rinha-postgres  | 2025-08-18 22:40:24.703 UTC [42] LOG:  checkpoint starting: shutdown immediate
python-rinha-postgres  | 2025-08-18 22:40:24.745 UTC [42] LOG:  checkpoint complete: wrote 928 buffers (5.7%); 0 WAL file(s) added, 0 removed, 0 recycled; write=0.025 s, sync=0.008 s, total=0.046 s; sync files=315, longest=0.003 s, average=0.001 s; distance=4284 kB, estimate=4284 kB
python-rinha-postgres  | 2025-08-18 22:40:24.801 UTC [41] LOG:  database system is shut down
python-rinha-postgres  |  done
python-rinha-postgres  | server stopped
python-rinha-postgres  | 
python-rinha-postgres  | PostgreSQL init process complete; ready for start up.
python-rinha-postgres  | 
python-rinha-postgres  | 2025-08-18 22:40:24.919 UTC [1] LOG:  starting PostgreSQL 15.13 on x86_64-pc-linux-musl, compiled by gcc (Alpine 14.2.0) 14.2.0, 64-bit
python-rinha-postgres  | 2025-08-18 22:40:24.919 UTC [1] LOG:  listening on IPv4 address "0.0.0.0", port 5432
python-rinha-postgres  | 2025-08-18 22:40:24.919 UTC [1] LOG:  listening on IPv6 address "::", port 5432
python-rinha-postgres  | 2025-08-18 22:40:24.926 UTC [1] LOG:  listening on Unix socket "/var/run/postgresql/.s.PGSQL.5432"
python-rinha-postgres  | 2025-08-18 22:40:24.934 UTC [59] LOG:  database system was shut down at 2025-08-18 22:40:24 UTC
python-rinha-postgres  | 2025-08-18 22:40:24.942 UTC [1] LOG:  database system is ready to accept connections
python-rinha-nginx     | 172.21.0.1 - - [18/Aug/2025:22:40:26 +0000] "GET /payments-summary HTTP/1.1" 499 0 "-" "curl/8.5.0"
python-rinha-nginx     | 172.21.0.1 - - [18/Aug/2025:22:40:34 +0000] "GET /payments-summary HTTP/1.1" 499 0 "-" "curl/8.5.0"
python-rinha-nginx     | 172.21.0.1 - - [18/Aug/2025:22:40:42 +0000] "GET /payments-summary HTTP/1.1" 499 0 "-" "curl/8.5.0"
python-rinha-nginx     | 172.21.0.1 - - [18/Aug/2025:22:40:50 +0000] "GET /payments-summary HTTP/1.1" 499 0 "-" "curl/8.5.0"
python-rinha-nginx     | 172.21.0.1 - - [18/Aug/2025:22:40:58 +0000] "GET /payments-summary HTTP/1.1" 499 0 "-" "curl/8.5.0"
python-rinha-nginx     | 172.21.0.1 - - [18/Aug/2025:22:41:06 +0000] "GET /payments-summary HTTP/1.1" 499 0 "-" "curl/8.5.0"
python-rinha-nginx     | 172.21.0.1 - - [18/Aug/2025:22:41:14 +0000] "GET /payments-summary HTTP/1.1" 499 0 "-" "curl/8.5.0"
python-rinha-nginx     | 172.21.0.1 - - [18/Aug/2025:22:41:22 +0000] "GET /payments-summary HTTP/1.1" 499 0 "-" "curl/8.5.0"
python-rinha-nginx     | 172.21.0.1 - - [18/Aug/2025:22:41:30 +0000] "GET /payments-summary HTTP/1.1" 499 0 "-" "curl/8.5.0"
python-rinha-nginx     | 172.21.0.1 - - [18/Aug/2025:22:41:38 +0000] "GET /payments-summary HTTP/1.1" 499 0 "-" "curl/8.5.0"
python-rinha-nginx     | 172.21.0.1 - - [18/Aug/2025:22:41:46 +0000] "GET /payments-summary HTTP/1.1" 499 0 "-" "curl/8.5.0"
python-rinha-nginx     | 172.21.0.1 - - [18/Aug/2025:22:41:54 +0000] "GET /payments-summary HTTP/1.1" 499 0 "-" "curl/8.5.0"
python-rinha-nginx     | 172.21.0.1 - - [18/Aug/2025:22:42:02 +0000] "GET /payments-summary HTTP/1.1" 499 0 "-" "curl/8.5.0"
python-rinha-nginx     | 172.21.0.1 - - [18/Aug/2025:22:42:10 +0000] "GET /payments-summary HTTP/1.1" 499 0 "-" "curl/8.5.0"
[Kpython-rinha-nginx exited with code 0
python-rinha-redis     | 1:signal-handler (1755556935) Received SIGTERM scheduling shutdown...
python-rinha-postgres  | 2025-08-18 22:42:15.808 UTC [1] LOG:  received fast shutdown request
python-rinha-postgres  | 2025-08-18 22:42:15.811 UTC [1] LOG:  aborting any active transactions
python-rinha-postgres  | 2025-08-18 22:42:15.815 UTC [1] LOG:  background worker "logical replication launcher" (PID 62) exited with exit code 1
python-rinha-postgres  | 2025-08-18 22:42:15.815 UTC [57] LOG:  shutting down
python-rinha-postgres  | 2025-08-18 22:42:15.818 UTC [57] LOG:  checkpoint starting: shutdown immediate
python-rinha-postgres  | 2025-08-18 22:42:15.839 UTC [57] LOG:  checkpoint complete: wrote 30 buffers (0.2%); 0 WAL file(s) added, 0 removed, 0 recycled; write=0.006 s, sync=0.005 s, total=0.024 s; sync files=13, longest=0.003 s, average=0.001 s; distance=65 kB, estimate=65 kB
python-rinha-redis     | 1:M 18 Aug 2025 22:42:15.843 * User requested shutdown...
python-rinha-redis     | 1:M 18 Aug 2025 22:42:15.843 * Calling fsync() on the AOF file.
python-rinha-redis     | 1:M 18 Aug 2025 22:42:15.843 * Saving the final RDB snapshot before exiting.
python-rinha-postgres  | 2025-08-18 22:42:15.846 UTC [1] LOG:  database system is shut down
python-rinha-redis     | 1:M 18 Aug 2025 22:42:15.849 * DB saved on disk
python-rinha-redis     | 1:M 18 Aug 2025 22:42:15.849 # Redis is now ready to exit, bye bye...
[Kpython-rinha-postgres exited with code 0
